Workbook

Sheet Leeme
A1: Experimento de la semana 1 · «Nada sin fuente»
A2: Celdas amarillas = las que se llenan a mano. Todo lo demás son fórmulas: no las editen.
A4: Paso 1 · Referencias (lo llena Anderson, sábado en la noche)
A5: Una fila por cada referencia que dio la IA: quién corrió la consulta, el texto de la consulta, el tratamiento (A, B o C), la referencia tal como la dio la IA, el DOI/URL que dio y la afirmación que le atribuyó. Si la IA no le atribuyó nada, escriban «(ninguna)».
A7: Paso 2 · Clasificación a ciegas (domingo)
A8: Cada integrante recibe su propia copia de este archivo con la hoja Referencias llena y solo llena SU hoja Clasif_<nombre>. No abre las hojas de los demás ni comenta con nadie hasta que los tres hayan entregado.
A9: Categorías: Utilizable = existe y dice lo que se le atribuye · Existe pero no dice eso = es real, pero la afirmación atribuida no se sostiene · No existe = no se encuentra por DOI ni por título.
A10: Reglas acordadas antes de clasificar (ver Anexo A del documento): si los metadatos están mal (año, volumen, páginas) pero el documento existe, se clasifica por contenido y se anota el error en Nota. Si solo se pudo leer el resumen, se anota «solo resumen».
A12: Paso 3 · Consolidación (Anderson)
A13: Copia la columna E de cada hoja Clasif_ recibida en la hoja del mismo nombre de este archivo maestro (mismas filas, mismo ID). Consolidado y Resultados se calculan solos.
A15: Cómo se calcula
A16: Clasificación final de cada referencia: la categoría que eligieron al menos dos de tres. Si los tres eligieron distinto queda «Sin mayoría» y se discute en equipo; la resolución se documenta, no se esconde.
... A21: ID R01 · Integrante: Isabella · Consulta: eficiencia del gasto público en educación superior en Colombia · Tratamiento: A · Referencia: Galvis-Aponte, L. (2015). La eficiencia del gasto público en educación en Colombia. Economía & Región, 9(2) · DOI/URL: (no dio) · Afirmación: «la eficiencia promedio en cobertura es 62,3 %»

Sheet Referencias
A1: ID | B1: Integrante (consulta) | C1: Consulta (texto exacto) | D1: Tratamiento | E1: Referencia tal como la dio la IA | F1: DOI / URL que dio la IA | G1: Afirmación que la IA le atribuye
A2: R01 | B2: Isabella | C2: Estoy elaborando el estado del arte de un proyecto de consultoría estadística sobre educación superior en Colombia. Dame cinco referencias académicas (artículos revisados por pares, libros o informes institucionales) sobre: el índice de Malmquist aplicado a universidades para medir el cambio de productividad entre periodos. Para cada una indica autores, año, título, revista o editorial, DOI o URL, y en una frase qué afirma o encuentra que sea relevante para mi pregunta. | D2: A | E2: Worthington, A. C., & Lee, B. L. (2008). Efficiency, technology and productivity change in Australian universities, 1998–2003. | F2: https://doi.org/10.1016/j.econedurev.2006.10.006 | G2: Worthington y Lee (2008) aplican el índice de Malmquist a 35 universidades australianas durante el periodo 1998-2003 para medir el crecimiento de la productividad y descomponerlo en cambios de eficiencia técnica y progreso tecnológico. El estudio encuentra un crecimiento promedio anual de la productividad del 3,3%, atribuido principalmente al progreso tecnológico.
A3: R02 | B3: Isabella | C3: Estoy elaborando el estado del arte de un proyecto de consultoría estadística sobre educación superior en Colombia. Dame cinco referencias académicas (artículos revisados por pares, libros o informes institucionales) sobre: el índice de Malmquist aplicado a universidades para medir el cambio de productividad entre periodos. Para cada una indica autores, año, título, revista o editorial, DOI o URL, y en una frase qué afirma o encuentra que sea relevante para mi pregunta. | D3: A | E3: Flegg, A. T., Allen, D. O., Field, K., & Thurlow, T. W. (2004). Measuring the efficiency of British universities: A multi-period data envelopment analysis | F3: https://doi.org/10.1080/0904529042000258586 | G3: Utiliza DEA en varios periodos para estudiar la evolución de la eficiencia universitaria y constituye un antecedente metodológico importante para analizar productividad y eficiencia a lo largo del tiempo.
A4: R03 | B4: Isabella | C4: Estoy elaborando el estado del arte de un proyecto de consultoría estadística sobre educación superior en Colombia. Dame cinco referencias académicas (artículos revisados por pares, libros o informes institucionales) sobre: el índice de Malmquist aplicado a universidades para medir el cambio de productividad entre periodos. Para cada una indica autores, año, título, revista o editorial, DOI o URL, y en una frase qué afirma o encuentra que sea relevante para mi pregunta. | D4: A | E4: Johnes, J. (2006). Data envelopment analysis and its application to the measurement of efficiency in higher education. | F4: https://doi.org/10.1016/j.econedurev.2005.02.005 | G4: Presenta y discute la aplicación de DEA en educación superior, explicando cómo las universidades pueden analizarse como unidades que transforman múltiples insumos en productos; es una base metodológica que posteriormente calcula índices de Malmquist.
A5: R04 | B5: Isabella | C5: Estoy elaborando el estado del arte de un proyecto de consultoría estadística sobre educación superior en Colombia. Dame cinco referencias académicas (artículos revisados por pares, libros o informes institucionales) sobre: el índice de Malmquist aplicado a universidades para medir el cambio de productividad entre periodos. Para cada una indica autores, año, título, revista o editorial, DOI o URL, y en una frase qué afirma o encuentra que sea relevante para mi pregunta. | D5: A | E5: Kao, C., & Hung, H.-T. (2008). Efficiency analysis of university departments: An empirical study. | F5: https://doi.org/10.1016/j.omega.2006.05.003 | G5: Muestra cómo DEA puede utilizarse para comparar unidades universitarias con múltiples insumos y productos, lo que resulta relevante cuando el índice de Malmquist se construye sobre fronteras de producción estimadas mediante DEA.
A6: R05 | B6: Isabella | C6: Estoy elaborando el estado del arte de un proyecto de consultoría estadística sobre educación superior en Colombia. Dame cinco referencias académicas (artículos revisados por pares, libros o informes institucionales) sobre: el índice de Malmquist aplicado a universidades para medir el cambio de productividad entre periodos. Para cada una indica autores, año, título, revista o editorial, DOI o URL, y en una frase qué afirma o encuentra que sea relevante para mi pregunta. | D6: A | E6: Abbott, M., & Doucouliagos, C. (2003). The efficiency of Australian universities: A data envelopment analysis. | F6: https://doi.org/10.1016/S0272-7757(01)00068-1 | G6: Analiza la eficiencia relativa de universidades australianas mediante DEA y demuestra la utilidad de este enfoque para estudiar diferencias de productividad/eficiencia entre instituciones de educación superior.
A7: R06 | B7: Isabella | C7: Estoy elaborando el estado del arte de un proyecto de consultoría estadística sobre educación superior en Colombia. Dame cinco referencias académicas (artículos revisados por pares, libros o informes institucionales) sobre: el índice de Malmquist aplicado a universidades para medir el cambio de productividad entre periodos. Para cada una indica autores, año, título, revista o editorial, DOI o URL, y en una frase qué afirma o encuentra que sea relevante para mi pregunta. | D7: B | E7: Johnes, J.(2008). Efficiency and Productivity Change in the English Higher Education Sector from 1996/97 to 2004/5 | F7: 10.1111/j.1467-9957.2008.01087.x | G7: Estima índices de Malmquist para 112 instituciones inglesas y encuentra un aumento medio anual de productividad de 1%, explicado por +6% de cambio tecnológico y −5% de eficiencia técnica
A8: R07 | B8: Isabella | C8: Estoy elaborando el estado del arte de un proyecto de consultoría estadística sobre educación superior en Colombia. Dame cinco referencias académicas (artículos revisados por pares, libros o informes institucionales) sobre: el índice de Malmquist aplicado a universidades para medir el cambio de productividad entre periodos. Para cada una indica autores, año, título, revista o editorial, DOI o URL, y en una frase qué afirma o encuentra que sea relevante para mi pregunta. | D8: B | E8: Parteka, A.; Wolszczak-Derlacz, J.(2012). Dynamics of productivity in higher education: cross-european evidence based on bootstrapped Malmquist indices | F8: 10.1007/s11123-012-0320-0 | G8: Analiza 266 instituciones públicas en 7 países europeos y muestra un crecimiento medio anual de productividad de 4%, además de evaluar la significancia estadística de los cambios con bootstrap
A9: R08 | B9: Isabella | C9: Estoy elaborando el estado del arte de un proyecto de consultoría estadística sobre educación superior en Colombia. Dame cinco referencias académicas (artículos revisados por pares, libros o informes institucionales) sobre: el índice de Malmquist aplicado a universidades para medir el cambio de productividad entre periodos. Para cada una indica autores, año, título, revista o editorial, DOI o URL, y en una frase qué afirma o encuentra que sea relevante para mi pregunta. | D9: B | E9: Worthington, A.; Lee, B. L.(Worthington, A.; Lee, B. L.(2008).Efficiency, technology and productivity change in Australian universities, 1998–2003 | F9: 10.1016/j.econedurev.2006.09.012 | G9: Para 35 universidades australianas, reporta un crecimiento anual medio de productividad de 3.3%, atribuido principalmente al progreso tecnológico; además separa productividad de docencia e investigación
A10: R09 | B10: Isabella | C10: Estoy elaborando el estado del arte de un proyecto de consultoría estadística sobre educación superior en Colombia. Dame cinco referencias académicas (artículos revisados por pares, libros o informes institucionales) sobre: el índice de Malmquist aplicado a universidades para medir el cambio de productividad entre periodos. Para cada una indica autores, año, título, revista o editorial, DOI o URL, y en una frase qué afirma o encuentra que sea relevante para mi pregunta. | D10: B | E10: García-Aracil, A.(2013). Understanding productivity changes in public universities: Evidence from Spain | F10: 10.1093/reseval/rvt009 | G10: Estudia universidades españolas entre 1994 y 2008 y encuentra que el crecimiento de productividad se debe más a mejoras de eficiencia que al progreso tecnológico, con un papel menor de la eficiencia de escala.
A11: R10 | B11: Isabella | C11: Estoy elaborando el estado del arte de un proyecto de consultoría estadística sobre educación superior en Colombia. Dame cinco referencias académicas (artículos revisados por pares, libros o informes institucionales) sobre: el índice de Malmquist aplicado a universidades para medir el cambio de productividad entre periodos. Para cada una indica autores, año, título, revista o editorial, DOI o URL, y en una frase qué afirma o encuentra que sea relevante para mi pregunta. | D11: B | E11: de la Hoz, E.; García-Yerena, C.; Zuluaga-Ortiz, R.(2026). Academic Productivity Dynamics in Colombian Social Science Programs: A PCA–Malmquist Index Approach (2020–2023) | F11: 10.7160/eriesj.2026.190107 | G11: Aplica PCA–Malmquist a 11,099 observaciones y concluye que 76% de las mejoras de productividad se explican por cambio tecnológico, con fuertes diferencias regionales
A12: R11 | B12: Isabella | C12: Estoy elaborando el estado del arte de un proyecto de consultoría estadística sobre educación superior en Colombia. Dame cinco referencias académicas (artículos revisados por pares, libros o informes institucionales) sobre: el índice de Malmquist aplicado a universidades para medir el cambio de productividad entre periodos. Para cada una indica autores, año, título, revista o editorial, DOI o URL, y en una frase qué afirma o encuentra que sea relevante para mi pregunta. | D12: C | E12: Francisco Javier Maza Ávila, Juan Carlos Vergara Schmalbach y Raúl Román Romero. (2017).Eficiencia y productividad en la cobertura de las universidades públicas colombianas | F12: https://www.google.com/url?sa=E&q=http%3A%2F%2Fwww.redalyc.org%2Farticulo.oa%3Fid%3D26854666001 | G12: Evalúa la evolución de la productividad en la cobertura de 32 universidades públicas colombianas (2003-2012) mediante el índice de Malmquist, encontrando un crecimiento promedio anual del 9% en la productividad impulsado fundamentalmente por avances tecnológicos
... A46: R45 | B46: Anderson | C46: Estoy elaborando el estado del arte de un proyecto de consultoría estadística sobre educación superior en Colombia. Dame cinco referencias académicas (artículos revisados por pares, libros o informes institucionales) sobre: el uso de resultados de pruebas estandarizadas de egreso (Saber Pro, ENADE, EGEL) como variable de producto en modelos DEA de eficiencia universitaria. Para cada una indica autores, año, título, revista o editorial, DOI o URL, y en una frase qué afirma o encuentra que sea relevante para mi pregunta. | D46: C | E46: Visbal-Cadavid, D., Martínez-Gómez, M., & Guijarro, F. (2017). Assessing the Efficiency of Public Universities through DEA. A Case Study. Sustainability, 9(8), 1416. | F46: https://doi.org/10.3390/su9081416 | G46: Evalúa 32 universidades públicas y consolida la metodología de medir la calidad de los egresados introduciendo en la frontera DEA el número ponderado de estudiantes en el quintil superior de Saber Pro.
A47: R46
A48: R47
A49: R48
A50: R49
A51: R50
A52: R51
A53: R52
A54: R53
A55: R54
A56: R55
A57: R56
A58: R57
... A73: R72

Sheet Clasif_Isabella
A1: ID | B1: Tratamiento | C1: Referencia | D1: Afirmación atribuida | E1: Clasificación | F1: Cómo la verifiqué (DOI/URL encontrado o búsqueda hecha) | G1: Nota (metadatos erróneos, solo resumen, etc.)
A2: =Referencias!A2 -> R01 | B2: =IF(Referencias!D2="","",Referencias!D2) -> A | C2: =IF(Referencias!E2="","",Referencias!E2) -> Worthington, A. C., & Lee, B. L. (2008). Efficiency, technology and productivity change in Australian universities, 1998–2003. | D2: =IF(Referencias!G2="","",Referencias!G2) -> Worthington y Lee (2008) aplican el índice de Malmquist a 35 universidades australianas durante el periodo 1998-2003 para medir el crecimiento de la productividad y descomponerlo en cambios de eficiencia técnica y progreso tecnológico. El estudio encuentra un crecimiento promedio anual de la productividad del 3,3%, atribuido principalmente al progreso tecnológico. | E2: Utilizable | F2: DOI dado no resolvió. Encontrado buscando título exacto + autores en Google. PDF en: DOI real: https://doi.org/10.1016/j.econedurev.2006.09.012. | G2: DOI incorrecto; el artículo existe.
A3: =Referencias!A3 -> R02 | B3: =IF(Referencias!D3="","",Referencias!D3) -> A | C3: =IF(Referencias!E3="","",Referencias!E3) -> Flegg, A. T., Allen, D. O., Field, K., & Thurlow, T. W. (2004). Measuring the efficiency of British universities: A multi-period data envelopment analysis | D3: =IF(Referencias!G3="","",Referencias!G3) -> Utiliza DEA en varios periodos para estudiar la evolución de la eficiencia universitaria y constituye un antecedente metodológico importante para analizar productividad y eficiencia a lo largo del tiempo. | E3: Utilizable | F3: DOI dado no resolvió. Encontrado buscando título exacto + autores en Google. PDF en: https://www.tandfonline.com/doi/full/10.1080/0904529042000258590?needAccess=true.DOI real: https://doi.org/10.1080/0904529042000258590. | G3: DOI incorrecto; solo resumen
A4: =Referencias!A4 -> R03 | B4: =IF(Referencias!D4="","",Referencias!D4) -> A | C4: =IF(Referencias!E4="","",Referencias!E4) -> Johnes, J. (2006). Data envelopment analysis and its application to the measurement of efficiency in higher education. | D4: =IF(Referencias!G4="","",Referencias!G4) -> Presenta y discute la aplicación de DEA en educación superior, explicando cómo las universidades pueden analizarse como unidades que transforman múltiples insumos en productos; es una base metodológica que posteriormente calcula índices de Malmquist. | E4: Existe pero no dice eso | F4: DOI dado resolvió (página oficial, acceso de pago). Texto completo en acceso libre encontrado en Google: https://scispace.com/pdf/data-envelopment-analysis-and-its-application-to-the-2prqruq09g.pdf. El artículo no menciona el índice de Malmquist ni cambios de productividad entre periodos.
A5: =Referencias!A5 -> R04 | B5: =IF(Referencias!D5="","",Referencias!D5) -> A | C5: =IF(Referencias!E5="","",Referencias!E5) -> Kao, C., & Hung, H.-T. (2008). Efficiency analysis of university departments: An empirical study. | D5: =IF(Referencias!G5="","",Referencias!G5) -> Muestra cómo DEA puede utilizarse para comparar unidades universitarias con múltiples insumos y productos, lo que resulta relevante cuando el índice de Malmquist se construye sobre fronteras de producción estimadas mediante DEA. | E5: Existe pero no dice eso | F5: DOI dado no resolvió. Encontrado buscando título exacto + autores en Google. PDF en: https://www.sciencedirect.com/science/article/abs/pii/S0305048306000211.DOI real: 10.1016/j.econedurev.2006.09.012. La parte de DEA y múltiples insumos/productos sí está, pero la referencia al índice de Malmquist no aparece en el resumen. | G5: DOI incorrecto; solo resumen
A6: =Referencias!A6 -> R05 | B6: =IF(Referencias!D6="","",Referencias!D6) -> A | C6: =IF(Referencias!E6="","",Referencias!E6) -> Abbott, M., & Doucouliagos, C. (2003). The efficiency of Australian universities: A data envelopment analysis. | D6: =IF(Referencias!G6="","",Referencias!G6) -> Analiza la eficiencia relativa de universidades australianas mediante DEA y demuestra la utilidad de este enfoque para estudiar diferencias de productividad/eficiencia entre instituciones de educación superior. | E6: Utilizable | F6: DOI dado resolvió (página oficial, acceso de pago). Texto completo en acceso libre encontrado en Google: https://www.researchgate.net/publication/222709271_The_Efficiency_of_Australian_Universities_A_Data_Envelopment_Analysis
A7: =Referencias!A7 -> R06 | B7: =IF(Referencias!D7="","",Referencias!D7) -> B | C7: =IF(Referencias!E7="","",Referencias!E7) -> Johnes, J.(2008). Efficiency and Productivity Change in the English Higher Education Sector from 1996/97 to 2004/5 | D7: =IF(Referencias!G7="","",Referencias!G7) -> Estima índices de Malmquist para 112 instituciones inglesas y encuentra un aumento medio anual de productividad de 1%, explicado por +6% de cambio tecnológico y −5% de eficiencia técnica | E7: Utilizable | F7: DOI dado resolvió (página oficial, acceso de pago). | G7: solo resumen
A8: =Referencias!A8 -> R07 | B8: =IF(Referencias!D8="","",Referencias!D8) -> B | C8: =IF(Referencias!E8="","",Referencias!E8) -> Parteka, A.; Wolszczak-Derlacz, J.(2012). Dynamics of productivity in higher education: cross-european evidence based on bootstrapped Malmquist indices | D8: =IF(Referencias!G8="","",Referencias!G8) -> Analiza 266 instituciones públicas en 7 países europeos y muestra un crecimiento medio anual de productividad de 4%, además de evaluar la significancia estadística de los cambios con bootstrap | E8: Utilizable | F8: DOI dado resolvió (página oficial). Texto completo encontrado en Google: https://link.springer.com/article/10.1007/s11123-012-0320-0
A9: =Referencias!A9 -> R08 | B9: =IF(Referencias!D9="","",Referencias!D9) -> B | C9: =IF(Referencias!E9="","",Referencias!E9) -> Worthington, A.; Lee, B. L.(Worthington, A.; Lee, B. L.(2008).Efficiency, technology and productivity change in Australian universities, 1998–2003 | D9: =IF(Referencias!G9="","",Referencias!G9) -> Para 35 universidades australianas, reporta un crecimiento anual medio de productividad de 3.3%, atribuido principalmente al progreso tecnológico; además separa productividad de docencia e investigación | E9: Utilizable | F9: DOI dado resolvió (página oficial). Texto completo encontrado en Google: https://external-apps.qut.edu.au/business/documents/discussionPapers/2005/No%20195%20-%20Worthington%20and%20%20Lee.pdf?utm_source=consensus
A10: =Referencias!A10 -> R09 | B10: =IF(Referencias!D10="","",Referencias!D10) -> B | C10: =IF(Referencias!E10="","",Referencias!E10) -> García-Aracil, A.(2013). Understanding productivity changes in public universities: Evidence from Spain | D10: =IF(Referencias!G10="","",Referencias!G10) -> Estudia universidades españolas entre 1994 y 2008 y encuentra que el crecimiento de productividad se debe más a mejoras de eficiencia que al progreso tecnológico, con un papel menor de la eficiencia de escala. | E10: Utilizable | F10: DOI dado resolvió (página oficial, acceso de pago). | G10: solo resumen
A11: =Referencias!A11 -> R10 | B11: =IF(Referencias!D11="","",Referencias!D11) -> B | C11: =IF(Referencias!E11="","",Referencias!E11) -> de la Hoz, E.; García-Yerena, C.; Zuluaga-Ortiz, R.(2026). Academic Productivity Dynamics in Colombian Social Science Programs: A PCA–Malmquist Index Approach (2020–2023) | D11: =IF(Referencias!G11="","",Referencias!G11) -> Aplica PCA–Malmquist a 11,099 observaciones y concluye que 76% de las mejoras de productividad se explican por cambio tecnológico, con fuertes diferencias regionales | E11: Existe pero no dice eso | F11: DOI dado resolvió .La cifra de 76 % aparece en el resumen; no la localicé en el cuerpo del artículo.
A12: =Referencias!A12 -> R11 | B12: =IF(Referencias!D12="","",Referencias!D12) -> C | C12: =IF(Referencias!E12="","",Referencias!E12) -> Francisco Javier Maza Ávila, Juan Carlos Vergara Schmalbach y Raúl Román Romero. (2017).Eficiencia y productividad en la cobertura de las universidades públicas colombianas | D12: =IF(Referencias!G12="","",Referencias!G12) -> Evalúa la evolución de la productividad en la cobertura de 32 universidades públicas colombianas (2003-2012) mediante el índice de Malmquist, encontrando un crecimiento promedio anual del 9% en la productividad impulsado fundamentalmente por avances tecnológicos | E12: Utilizable | F12: DOI dado resolvió.
A13: =Referencias!A13 -> R12 | B13: =IF(Referencias!D13="","",Referencias!D13) -> C | C13: =IF(Referencias!E13="","",Referencias!E13) -> Morales-Piñero, Niño-Muñoz, & Lesmes-Cardenas (2022).Gestión Pública o Privada de las Universidades: ¿Cuál es la Opción más Eficiente para una Política Pública en Educación Superior en Colombia? | D13: =IF(Referencias!G13="","",Referencias!G13) -> Emplea el índice Global Malmquist-Luenberger (GML) con metafronteras DEA para evaluar la productividad y la eficiencia de 122 universidades públicas y privadas colombianas considerando bad outputs como los egresados no vinculados al mercado laboral formal | E13: Utilizable | F13: DOI dado resolvió.
A14: =Referencias!A14 -> R13 | B14: =IF(Referencias!D14="","",Referencias!D14) -> C | C14: =IF(Referencias!E14="","",Referencias!E14) -> Thanassoulis, Kortelainen, Johnes, & Johnes (2011).Costs and efficiency of higher education institutions in England: A DEA analysis. | D14: =IF(Referencias!G14="","",Referencias!G14) -> Utiliza el índice de Malmquist combinado con modelos DEA para medir las variaciones en la productividad total de los factores a lo largo del tiempo y analizar las estructuras de costos en las instituciones de educación superior en Inglaterra. | E14: Utilizable | F14: DOI dado resolvió (página oficial, acceso de pago). Texto completo encontrado en Google:https://www.researchgate.net/publication/23978449_Costs_and_Efficiency_of_Higher_Education_Institutions_in_England_A_DEA_Analysis
A15: =Referencias!A15 -> R14 | B15: =IF(Referencias!D15="","",Referencias!D15) -> C | C15: =IF(Referencias!E15="","",Referencias!E15) -> Flegg, Allen, Field, & Thurlow (2004).Measuring the efficiency of British universities: A multiperiod data envelopment analysis. | D15: =IF(Referencias!G15="","",Referencias!G15) -> Mide los cambios en la productividad y la eficiencia técnica de las universidades británicas en múltiples periodos aplicando el índice de Malmquist, evaluando además el impacto de la congestión de insumos en el rendimiento. | E15: Utilizable | F15: DOI dado resolvió (página oficial, acceso de pago).
A16: =Referencias!A16 -> R15 | B16: =IF(Referencias!D16="","",Referencias!D16) -> C | C16: =IF(Referencias!E16="","",Referencias!E16) -> Galvis-Aponte (2015). LA EFICIENCIA DEL GASTO PÚBLICO EN EDUCACIÓN EN COLOMBIA | D16: =IF(Referencias!G16="","",Referencias!G16) -> Evalúa la eficiencia del gasto territorial del Sistema General de Participaciones (SGP) en municipios colombianos (2012), encontrando una eficiencia promedio de 63,4% en cobertura y de 48,8% en calidad educativa. | E16: Utilizable | F16: URL correcto.
A17: =Referencias!A17 -> R16 | B17: =IF(Referencias!D17="","",Referencias!D17) -> A | C17: =IF(Referencias!E17="","",Referencias!E17) -> Melo-Becerra, L. A., & Vásquez, D. M. (2019). Eficiencia de las instituciones de educación superior en Colombia: una aproximación mediante análisis envolvente de datos | D17: =IF(Referencias!G17="","",Referencias!G17) -> Es directamente pertinente para Colombia: utiliza DEA para estudiar diferencias de eficiencia entre instituciones de educación superior y permite sustentar la selección de insumos y productos educativos en un contexto colombiano. | E17: No existe | F17: Link dado no abre (error 404). | G17: Se tiene un articulo con el mismo nombre, sin embargo, los autores y feche de publicación no coinciden, por eso, se deja la decisión de no existe, porque no se tiene un factor para comparar.
A18: =Referencias!A18 -> R17 | B18: =IF(Referencias!D18="","",Referencias!D18) -> A | C18: =IF(Referencias!E18="","",Referencias!E18) -> González, L., & Callejas, J. (2011). Análisis envolvente de datos aplicado a la evaluación de la eficiencia de las universidades públicas españolas | D18: =IF(Referencias!G18="","",Referencias!G18) -> Es útil metodológicamente porque muestra cómo DEA permite comparar universidades mediante una frontera de eficiencia, distinguiendo instituciones eficientes de aquellas con posibilidades de mejora relativa. | E18: No existe | F18: Sin resultados en google.
A19: =Referencias!A19 -> R18 | B19: =IF(Referencias!D19="","",Referencias!D19) -> A | C19: =IF(Referencias!E19="","",Referencias!E19) -> Johnes, J. (2006). Data envelopment analysis and its application to the measurement of efficiency in higher education | D19: =IF(Referencias!G19="","",Referencias!G19) -> Es relevante para justificar comparaciones entre instituciones públicas y otros tipos de universidades y para discutir cómo las características institucionales pueden asociarse con diferencias en eficiencia DEA. | E19: Utilizable | F19: DOI dado resolvió (página oficial, acceso de pago). Texto completo encontrado en Google:https://scispace.com/pdf/data-envelopment-analysis-and-its-application-to-the-2prqruq09g.pdf
A20: =Referencias!A20 -> R19 | B20: =IF(Referencias!D20="","",Referencias!D20) -> A | C20: =IF(Referencias!E20="","",Referencias!E20) -> Agasisti, T., Dal Bianco, A., Griffini, M., & Valenti, R. (2016). The public-private efficiency gap: An empirical analysis of Italian universities | D20: =IF(Referencias!G20="","",Referencias!G20) -> Es directamente pertinente para Colombia: utiliza DEA para estudiar diferencias de eficiencia entre instituciones de educación superior y permite sustentar la selección de insumos y productos educativos en un contexto colombiano. | E20: No existe | F20: Sin resultados en google, la referencia no incluia URL ni DOI, al momento de realizar la busqueda directamente por el nombre, no se obtuvo ningún resultado del texto de referencia.
A21: =Referencias!A21 -> R20 | B21: =IF(Referencias!D21="","",Referencias!D21) -> A | C21: =IF(Referencias!E21="","",Referencias!E21) -> Ramanathan, R. (2003). An Introduction to Data Envelopment Analysis: A Tool for Performance Measurement | D21: =IF(Referencias!G21="","",Referencias!G21) -> Aunque no es específico de universidades latinoamericanas, proporciona la base metodológica para CCR/BCC, orientación input/output, eficiencia técnica y construcción de la frontera DEA, conceptos necesarios para fundamentar el modelo de tu consultoría. | E21: Existe pero no dice eso | F21: Link dado no abre (error 404), el link de referencia que se proporciona no dirige a ninguna pagina, lo que se obtiene es un error, y al buscar el texto directamente en google teniendo en cuenta el nombre del autoor, se obtiene que toca pagar y no sé encuentra información verificada sobre un resumen de este mismo.
A22: =Referencias!A22 -> R21 | B22: =IF(Referencias!D22="","",Referencias!D22) -> B | C22: =IF(Referencias!E22="","",Referencias!E22) -> Lina P. Navas, Felipe Montes, Sepideh Abolghasem, Ricardo Salas, M. Toloo, R. Zarama (2020) Colombian higher education institutions evaluation | D22: =IF(Referencias!G22="","",Referencias!G22) -> Propone una extensión de DEA de eficiencia cruzada para evaluar IES colombianas con metas múltiples, mostrando que unas instituciones son más eficientes en docencia o empleabilidad y otras en investigación | E22: Utilizable | F22: DOI dado resolvió (página oficial, acceso de pago). Se verifico que al articulo existe y tambien que el DOI funciona, sin embargop, al buscar el texto competo no se logro obtener, ya que, es de acceso, pago, aún así el resumen proporcionadop de la página oficial establece que el hallazgo obtenido está presente en el aticulo obtenido. | G22: solo resumen
A23: =Referencias!A23 -> R22 | B23: =IF(Referencias!D23="","",Referencias!D23) -> B | C23: =IF(Referencias!E23="","",Referencias!E23) -> Delimiro Visbal-Cadavid, M. Martínez-Gómez, F. Guijarro (2017) Assessing the Efficiency of Public Universities through DEA. A Case Study | D23: =IF(Referencias!G23="","",Referencias!G23) -> Evalúa 32 universidades públicas colombianas con modelos CCR, BCC y SBM orientados al output, desagregando ineficiencia técnica, de escala y de mezcla, y encuentra a Tolima, Caldas y UNAD entre las de mejor desempeño. | E23: Utilizable | F23: DOI dado resolvió.
A24: =Referencias!A24 -> R23 | B24: =IF(Referencias!D24="","",Referencias!D24) -> B | C24: =IF(Referencias!E24="","",Referencias!E24) -> Jorge Moreno-Gómez, Jonathan Calleja-Blanco, Gloria Moreno-Gómez (2019) Measuring the efficiency of the Colombian higher education system: a two-stage approach | D24: =IF(Referencias!G24="","",Referencias!G24) -> Aplica un DEA en dos etapas a 78 universidades colombianas entre 2015 y 2017 y encuentra que las públicas superan a las privadas en eficiencia docente e investigativa, mientras la proporción de profesores con PhD mejora todas las dimensiones de eficiencia | E24: Utilizable | F24: DOI dado resolvió (página oficial, acceso de pago), sin embargo, se verifico con el resumen de la página oficial y esta información coincide con el hallazgo proporcionado. | G24: solo resumen
A25: =Referencias!A25 -> R24 | B25: =IF(Referencias!D25="","",Referencias!D25) -> B | C25: =IF(Referencias!E25="","",Referencias!E25) -> M. Sagarra, T. Agasisti (2017) Exploring the efficiency of Mexican universities: Integrating Data Envelopment Analysis and Multidimensional Scaling | D25: =IF(Referencias!G25="","",Referencias!G25) -> Analiza 55 universidades mexicanas entre 2007 y 2012 con 21 modelos DEA y escalamiento multidimensional, para distinguir si los cambios de eficiencia provienen de docencia, investigación o ambas dimensiones | E25: Utilizable | F25: DOI dado resolvió (página oficial, acceso de pago), sin embargo, se verifico con el resumen de la página oficial y esta información coincide con el hallazgo proporcionado. | G25: solo resumen
A26: =Referencias!A26 -> R25 | B26: =IF(Referencias!D26="","",Referencias!D26) -> B | C26: =IF(Referencias!E26="","",Referencias!E26) -> Rafael Santos Tavares, L. Angulo-Meza, A. P. Sant'Anna (2021) A proposed multistage evaluation approach for Higher Education Institutions based on network Data envelopment analysis: A Brazilian experience | D26: =IF(Referencias!G26="","",Referencias!G26) -> Desarrolla un enfoque de Network DEA en tres etapas aplicado a 45 universidades federales brasileñas, permitiendo medir eficiencia financiera, de pregrado y de posgrado con una visión más integral de los procesos universitarios | E26: Utilizable | F26: DOI dado resolvió (página oficial, acceso de pago). Solo se tienen acceso al resumen, este mismo se relaciona con la información dada en el hallazgo, sin embargo, no sé logra confirmar con el articulo completo. | G26: solo resumen
A27: =Referencias!A27 -> R26 | B27: =IF(Referencias!D27="","",Referencias!D27) -> C | C27: =IF(Referencias!E27="","",Referencias!E27) -> Francisco Javier Maza Ávila, Juan Carlos Vergara Schmalbach y Raúl Román Romero (2017) EFICIENCIA Y PRODUCTIVIDAD EN LA COBERTURA DE LAS UNIVERSIDADES PÚBLICAS COLOMBIANAS | D27: =IF(Referencias!G27="","",Referencias!G27) -> Analiza la eficiencia técnica (DEA BCC) y los cambios en la productividad (índice de Malmquist) en la cobertura de 32 universidades públicas colombianas del Sistema Universitario Estatal (2003-2012), encontrando una eficiencia promedio superior al 70% y un crecimiento de la productividad del 9%, aunque con notables diferencias entre la región Andina y la región Caribe | E27: Utilizable | F27: Link dado no abre (error 404), el link de referencia que se proporciona no dirige a ninguna pagina, lo que se obtiene es un error, sin embargo, al buscar el nombre del texto directamente en google, se obtiene acceso completo a este mismo. https://www.redalyc.org/journal/268/26854666001/html/
A28: =Referencias!A28 -> R27 | B28: =IF(Referencias!D28="","",Referencias!D28) -> C | C28: =IF(Referencias!E28="","",Referencias!E28) -> Juan Morales-Piñero, Diana Niño-Muñoz y Diana Lesmes-Cardenas (2022) Gestión Pública o Privada de las Universidades: ¿Cuál es la Opción más Eficiente para una Política Pública en Educación Superior en Colombia? | D28: =IF(Referencias!G28="","",Referencias!G28) -> Compara la eficiencia de 122 universidades públicas y privadas colombianas mediante una metafrontera DEA con *bad outputs* (incorporando el desempleo formal de sus graduados), concluyendo que no hay diferencias globales estadísticamente significativas en la eficiencia de gestión entre ambos sectores, aunque las universidades públicas lideran la producción científica y muestran mayor eficiencia en entornos urbanos de alta competencia | E28: Utilizable | F28: DOI dado resolvió.
A29: =Referencias!A29 -> R28 | B29: =IF(Referencias!D29="","",Referencias!D29) -> C | C29: =IF(Referencias!E29="","",Referencias!E29) -> Diego Visbal-Cadavid, Adel Mendoza y Eduardo Causado Rodríguez (2016) Eficiencia en las instituciones de educación superior públicas colombianas: una aplicación del análisis envolvente de datos | D29: =IF(Referencias!G29="","",Referencias!G29) -> Aplica la metodología DEA para medir la eficiencia relativa de las instituciones públicas de educación superior en Colombia al transformar sus recursos institucionales e insumos en productos de docencia e investigación | E29: Utilizable | F29: Link dado no abre (error 404), el link de referencia que se proporciona no dirige a ninguna pagina, lo que se obtiene es un error, sin embargo, al buscar el nombre del texto directamente en google, se obtiene acceso completo a este mismo. https://www.redalyc.org/journal/1002/100246672006/html/
A30: =Referencias!A30 -> R29 | B30: =IF(Referencias!D30="","",Referencias!D30) -> C | C30: =IF(Referencias!E30="","",Referencias!E30) -> Zulima Ramírez-Gutiérrez, Mercedes Barrachina-Palanca y Vicente Ripoll-Feliu (2020) Efficiency in higher education. Empirical study in public universities of Colombia and Spain[18] | D30: =IF(Referencias!G30="","",Referencias!G30) -> Realiza una evaluación empírica mediante Análisis Envolvente de Datos para comparar el desempeño e identificar niveles de eficiencia técnica e institucional entre las universidades públicas de Colombia y España | E30: Utilizable | F30: Link dado no abre (error 404), el link de referencia que se proporciona no dirige a ninguna pagina, lo que se obtiene es un error, sin embargo, al buscar el nombre del texto directamente en google, se obtiene acceso completo a este mismo. https://www.redalyc.org/journal/2410/241064754007/241064754007.pdf | G30: En la referencia dada por la IA, se conmfirmo que está mal el nombre de uno de los autores del texto, la referencia correcta es : Zoraida Ramírez-Gutiérrez, Mercedes Barrachina-Palanca y Vicente Ripoll-Feliu (2020) Efficiency in higher education. Empirical study in public universities of Colombia and Spain[18]
A31: =Referencias!A31 -> R30 | B31: =IF(Referencias!D31="","",Referencias!D31) -> C | C31: =IF(Referencias!E31="","",Referencias!E31) -> Alejandro Altamirano-Corro y Rodrigo Peniche-Vera (2014) Measuring the institutional efficiency using DEA and AHP: The case of a Mexican university | D31: =IF(Referencias!G31="","",Referencias!G31) -> Combina el Análisis Envolvente de Datos con el Proceso de Análisis Jerárquico (AHP) para evaluar la eficiencia institucional y la gestión con múltiples entradas y salidas en el ámbito universitario público en México | E31: Utilizable | F31: Link dado no dirige a ninguna pagina, lo que se obtiene es un error, sin embargo, al buscar el nombre del texto directamente en google, se obtiene acceso completo a este mismo. https://www.researchgate.net/publication/276427961_Measuring_the_Institutional_Efficiency_Using_DEA_and_AHP_the_Case_of_a_Mexican_University | G31: En la referencia dada por la IA, los nombres de los autores están mal. Antonio Altamirano-Corro y Rebeca del Rocío Peniche-Vera (2014)
A32: =Referencias!A32 -> R31 | B32: =IF(Referencias!D32="","",Referencias!D32) -> A | C32: =IF(Referencias!E32="","",Referencias!E32) -> Zuluaga, R., Delahoz-Domínguez, E. J., & Ojeda, H. (2020). Eficiencia académica estudiantil: un enfoque de análisis de componentes principales y análisis envolvente de datos. | D32: =IF(Referencias!G32="","",Referencias!G32) -> Propone combinar PCA y DEA para medir la eficiencia académica a partir de los resultados de Saber Pro 2018 y encuentra que solo el 16,67 % de las unidades analizadas fueron eficientes, identificando competencias específicas susceptibles de mejora. | E32: Utilizable | F32: DOI dado resolvió.
A33: =Referencias!A33 -> R32 | B33: =IF(Referencias!D33="","",Referencias!D33) -> A | C33: =IF(Referencias!E33="","",Referencias!E33) -> De La Hoz, E., Zuluaga, R., & Mendoza, A. (2021). Assessing and Classification of Academic Efficiency in Engineering Teaching Programs. | D33: =IF(Referencias!G33="","",Referencias!G33) -> Es muy pertinente para tu problema porque define explícitamente los Saber 11 como inputs y los Saber Pro como outputs del DEA, aplicándolo a 265 programas de ingeniería y resaltando la importancia de comparar instituciones con características similares. | E33: Utilizable | F33: DOI dado resolvió.
A34: =Referencias!A34 -> R33 | B34: =IF(Referencias!D34="","",Referencias!D34) -> A | C34: =IF(Referencias!E34="","",Referencias!E34) -> Zuluaga, R., Camelo-Guarín, A., & De La Hoz, E. (2023). Assessing the Relative Impact of Colombian Higher Education Institutions Using Fuzzy Data Envelopment Analysis (Fuzzy-DEA) in State Evaluations. | D34: =IF(Referencias!G34="","",Referencias!G34) -> Aplica Fuzzy-DEA a 92 instituciones y 4.976 estudiantes de Ingeniería Industrial, usando Saber 11 como inputs y Saber Pro como outputs, y muestra cómo la frontera de eficiencia puede interpretarse como una ruta de incremento de resultados entre ambas pruebas. | E34: Utilizable | F34: DOI dado resolvió.
A35: =Referencias!A35 -> R34 | B35: =IF(Referencias!D35="","",Referencias!D35) -> A | C35: =IF(Referencias!E35="","",Referencias!E35) -> Mendoza-Mendoza, A., De La Hoz-Domínguez, E. J., & Visbal-Cadavid, D. (2023). Classification of industrial engineering programs in Colombia based on state tests. | D35: =IF(Referencias!G35="","",Referencias!G35) -> Utiliza un DEA-BCC orientado a outputs, con resultados de Saber 11 como entradas y Saber Pro como salidas, para 5.318 estudiantes de 93 IES; las eficiencias obtenidas permiten clasificar los programas en tres grupos y muestran directamente la utilidad de tratar el resultado de egreso como producto educativo. | E35: Utilizable | F35: DOI dado resolvió.
A36: =Referencias!A36 -> R35 | B36: =IF(Referencias!D36="","",Referencias!D36) -> A | C36: =IF(Referencias!E36="","",Referencias!E36) -> Marques, F. C., Davoglio, G. R., Gabardo da Camara, M. R., do Nascimento, S. P., & Ferreira, C. R. (2021). Efficiency Comparison Between Public and Private Higher Education Institutions in the Academic Performance of Economics Senior Students. | D36: =IF(Referencias!G36="","",Referencias!G36) -> Para ENADE, desarrolla una DEA descompuesta en una componente asociada al desempeño del estudiante y otra a la eficiencia de la IES, utilizando los resultados de estudiantes de Economía de 2012 y 2015 y controlando además factores socioeconómicos. | E36: Utilizable | F36: DOI dado resolvió.
A37: =Referencias!A37 -> R36 | B37: =IF(Referencias!D37="","",Referencias!D37) -> B | C37: =IF(Referencias!E37="","",Referencias!E37) -> Zuluaga-Ortiz, R., Delahoz-Domínguez, E. J., & Camelo-Guarín, A. (2022). Academic efficiency of engineering university degrees and its driving factors. A PLS-DEA approach. Journal of International Studies. | D37: =IF(Referencias!G37="","",Referencias!G37) -> Usa explícitamente los resultados de Saber Pro como outputs y los de Saber 11 como inputs para modelar la transformación educativa en programas de ingeniería en Colombia. | E37: Utilizable | F37: DOI dado resolvió.
A38: =Referencias!A38 -> R37 | B38: =IF(Referencias!D38="","",Referencias!D38) -> B | C38: =IF(Referencias!E38="","",Referencias!E38) -> Visbal-Cadavid, D., Martínez-Gómez, M., & Guijarro, F. (2017). Assessing the Efficiency of Public Universities through DEA. A Case Study. Sustainability. | D38: =IF(Referencias!G38="","",Referencias!G38) -> Incluye Saber Pro Top Quintile como variable de producto en un DEA orientado a outputs para universidades públicas colombianas, y muestra que casi todas las IES ineficientes requerían mejorar ese resultado para alcanzar la frontera. | E38: Utilizable | F38: DOI dado resolvió.
A39: =Referencias!A39 -> R38 | B39: =IF(Referencias!D39="","",Referencias!D39) -> B | C39: =IF(Referencias!E39="","",Referencias!E39) -> Tavares, R. S., Angulo-Meza, L., & Sant'Anna, A. P. (2021). A proposed multistage evaluation approach for Higher Education Institutions based on network Data envelopment analysis: A Brazilian experience. Evaluation and Program Planning. | D39: =IF(Referencias!G39="","",Referencias!G39) -> Propone un Network DEA para 45 universidades federales brasileñas con una etapa de pregrado, consistente con el uso de indicadores de desempeño formativo tipo ENADE dentro de una evaluación multietapa, aunque el extracto no nombra la variable exacta. | E39: Existe pero no dice eso | F39: DOI dado resolvió (página oficial, acceso de pago). Solo se tienen acceso al resumen y este no nombra la variable exacta (ENADE). | G39: solo resumen
A40: =Referencias!A40 -> R39 | B40: =IF(Referencias!D40="","",Referencias!D40) -> B | C40: =IF(Referencias!E40="","",Referencias!E40) -> Moreno-Gómez, J., Calleja-Blanco, J., & Moreno-Gómez, G. (2019). Measuring the efficiency of the Colombian higher education system: a two-stage approach. International Journal of Educational Management. | D40: =IF(Referencias!G40="","",Referencias!G40) -> Es un antecedente metodológico útil de DEA en universidades colombianas y de análisis en dos etapas, aunque el extracto disponible no confirma que use Saber Pro como output específico. | E40: Existe pero no dice eso | F40: DOI dado resolvió (página oficial, acceso de pago). Texto completo encontrado en Google:https://share.google/PO6DrrcHLyGzPeRYd | G40: Efectivamente en el artÍculo encontrado, no se tiene informacion del Saber pro como output específico.
...

Sheet Clasif_Eduar
A1: ID | B1: Tratamiento | C1: Referencia | D1: Afirmación atribuida | E1: Clasificación | F1: Cómo la verifiqué (DOI/URL encontrado o búsqueda hecha) | G1: Nota (metadatos erróneos, solo resumen, etc.)
A2: =Referencias!A2 -> R01 | B2: =IF(Referencias!D2="","",Referencias!D2) -> A | C2: =IF(Referencias!E2="","",Referencias!E2) -> Worthington, A. C., & Lee, B. L. (2008). Efficiency, technology and productivity change in Australian universities, 1998–2003. | D2: =IF(Referencias!G2="","",Referencias!G2) -> Worthington y Lee (2008) aplican el índice de Malmquist a 35 universidades australianas durante el periodo 1998-2003 para medir el crecimiento de la productividad y descomponerlo en cambios de eficiencia técnica y progreso tecnológico. El estudio encuentra un crecimiento promedio anual de la productividad del 3,3%, atribuido principalmente al progreso tecnológico. | E2: Utilizable | F2: El DOI proporcionado no funciona. Sin embargo, al buscar la referencia en el buscador web y en Google Académico se localizó el artículo correspondiente. El texto completo requiere pago y únicamente fue posible consultar el resumen. | G2: La existencia de la referencia pudo confirmarse, pero la verificación del contenido se limitó al resumen debido al acceso restringido al texto completo.
A3: =Referencias!A3 -> R02 | B3: =IF(Referencias!D3="","",Referencias!D3) -> A | C3: =IF(Referencias!E3="","",Referencias!E3) -> Flegg, A. T., Allen, D. O., Field, K., & Thurlow, T. W. (2004). Measuring the efficiency of British universities: A multi-period data envelopment analysis | D3: =IF(Referencias!G3="","",Referencias!G3) -> Utiliza DEA en varios periodos para estudiar la evolución de la eficiencia universitaria y constituye un antecedente metodológico importante para analizar productividad y eficiencia a lo largo del tiempo. | E3: Utilizable | F3: El DOI proporcionado no funciona. Sin embargo, al buscar la referencia en el buscador web y en Google Académico se localizó el artículo correspondiente. El texto completo requiere pago y únicamente fue posible consultar el resumen. | G3: La existencia de la referencia pudo confirmarse, pero la verificación del contenido se limitó al resumen debido al acceso restringido al texto completo.
A4: =Referencias!A4 -> R03 | B4: =IF(Referencias!D4="","",Referencias!D4) -> A | C4: =IF(Referencias!E4="","",Referencias!E4) -> Johnes, J. (2006). Data envelopment analysis and its application to the measurement of efficiency in higher education. | D4: =IF(Referencias!G4="","",Referencias!G4) -> Presenta y discute la aplicación de DEA en educación superior, explicando cómo las universidades pueden analizarse como unidades que transforman múltiples insumos en productos; es una base metodológica que posteriormente calcula índices de Malmquist. | E4: Utilizable | F4: El DOI proporcionado funciona correctamente y el artículo aparece también en Google Académico. Aunque la página principal solo permite consultar el resumen, se localizó otra fuente donde fue posible acceder al artículo completo. La lectura del artículo confirma la afirmación atribuida por la IA. | G4: La referencia y la afirmación fueron verificadas directamente en el texto completo disponible.
A5: =Referencias!A5 -> R04 | B5: =IF(Referencias!D5="","",Referencias!D5) -> A | C5: =IF(Referencias!E5="","",Referencias!E5) -> Kao, C., & Hung, H.-T. (2008). Efficiency analysis of university departments: An empirical study. | D5: =IF(Referencias!G5="","",Referencias!G5) -> Muestra cómo DEA puede utilizarse para comparar unidades universitarias con múltiples insumos y productos, lo que resulta relevante cuando el índice de Malmquist se construye sobre fronteras de producción estimadas mediante DEA. | E5: Utilizable | F5: El DOI proporcionado funciona y el artículo aparece también en Google Académico. Sin embargo, la página consultada únicamente permite acceder al resumen y el texto completo requiere pago. | G5: La existencia y los metadatos del artículo fueron confirmados, pero no fue posible verificar completamente la afirmación debido al acceso restringido al texto completo.
A6: =Referencias!A6 -> R05 | B6: =IF(Referencias!D6="","",Referencias!D6) -> A | C6: =IF(Referencias!E6="","",Referencias!E6) -> Abbott, M., & Doucouliagos, C. (2003). The efficiency of Australian universities: A data envelopment analysis. | D6: =IF(Referencias!G6="","",Referencias!G6) -> Analiza la eficiencia relativa de universidades australianas mediante DEA y demuestra la utilidad de este enfoque para estudiar diferencias de productividad/eficiencia entre instituciones de educación superior. | E6: Utilizable | F6: El DOI proporcionado permite consultar el resumen y la referencia también aparece en Google Académico. Mediante una búsqueda adicional en el buscador web se localizó una fuente que permite consultar el artículo completo; sin embargo, la coincidencia con la afirmación de la IA se pudo confirmar a partir de la información del resumen disponible. | G6: La referencia pudo ser localizada y la afirmación coincide con el resumen, pero la verificación del contenido fue parcial.
A7: =Referencias!A7 -> R06 | B7: =IF(Referencias!D7="","",Referencias!D7) -> B | C7: =IF(Referencias!E7="","",Referencias!E7) -> Johnes, J.(2008). Efficiency and Productivity Change in the English Higher Education Sector from 1996/97 to 2004/5 | D7: =IF(Referencias!G7="","",Referencias!G7) -> Estima índices de Malmquist para 112 instituciones inglesas y encuentra un aumento medio anual de productividad de 1%, explicado por +6% de cambio tecnológico y −5% de eficiencia técnica | E7: Utilizable | F7: El DOI proporcionado funciona, aunque inicialmente solo permite consultar el resumen. Mediante una búsqueda adicional en el buscador web se encontró una fuente que permite descargar el artículo completo en formato Word. La lectura del documento confirma la afirmación atribuida por la IA. | G7: La referencia y la afirmación fueron verificadas directamente en el texto completo localizado en una fuente alternativa.
A8: =Referencias!A8 -> R07 | B8: =IF(Referencias!D8="","",Referencias!D8) -> B | C8: =IF(Referencias!E8="","",Referencias!E8) -> Parteka, A.; Wolszczak-Derlacz, J.(2012). Dynamics of productivity in higher education: cross-european evidence based on bootstrapped Malmquist indices | D8: =IF(Referencias!G8="","",Referencias!G8) -> Analiza 266 instituciones públicas en 7 países europeos y muestra un crecimiento medio anual de productividad de 4%, además de evaluar la significancia estadística de los cambios con bootstrap | E8: Utilizable | F8: El DOI proporcionado funciona correctamente y permite visualizar el PDF completo del artículo. La lectura del documento confirma la afirmación atribuida por la IA. | G8: La referencia, el acceso al texto completo y la afirmación fueron confirmados directamente en el artículo.
A9: =Referencias!A9 -> R08 | B9: =IF(Referencias!D9="","",Referencias!D9) -> B | C9: =IF(Referencias!E9="","",Referencias!E9) -> Worthington, A.; Lee, B. L.(Worthington, A.; Lee, B. L.(2008).Efficiency, technology and productivity change in Australian universities, 1998–2003 | D9: =IF(Referencias!G9="","",Referencias!G9) -> Para 35 universidades australianas, reporta un crecimiento anual medio de productividad de 3.3%, atribuido principalmente al progreso tecnológico; además separa productividad de docencia e investigación | E9: Utilizable | F9: El DOI y la referencia conducen al artículo correspondiente, pero el texto completo requiere pago. Únicamente fue posible consultar el resumen, el cual coincide con la afirmación o relevancia atribuida por la IA. | G9: La existencia y los metadatos fueron confirmados, pero la verificación del contenido se limitó al resumen.
A10: =Referencias!A10 -> R09 | B10: =IF(Referencias!D10="","",Referencias!D10) -> B | C10: =IF(Referencias!E10="","",Referencias!E10) -> García-Aracil, A.(2013). Understanding productivity changes in public universities: Evidence from Spain | D10: =IF(Referencias!G10="","",Referencias!G10) -> Estudia universidades españolas entre 1994 y 2008 y encuentra que el crecimiento de productividad se debe más a mejoras de eficiencia que al progreso tecnológico, con un papel menor de la eficiencia de escala. | E10: Utilizable | F10: El DOI conduce al artículo y este también aparece en Google Académico. Aunque estas fuentes solo permiten consultar el resumen, mediante una búsqueda adicional en el buscador web se localizó el artículo completo. La lectura del texto confirma la relevancia atribuida por la IA. | G10: La referencia y la afirmación fueron verificadas directamente en el texto completo disponible en una fuente alternativa.
A11: =Referencias!A11 -> R10 | B11: =IF(Referencias!D11="","",Referencias!D11) -> B | C11: =IF(Referencias!E11="","",Referencias!E11) -> de la Hoz, E.; García-Yerena, C.; Zuluaga-Ortiz, R.(2026). Academic Productivity Dynamics in Colombian Social Science Programs: A PCA–Malmquist Index Approach (2020–2023) | D11: =IF(Referencias!G11="","",Referencias!G11) -> Aplica PCA–Malmquist a 11,099 observaciones y concluye que 76% de las mejoras de productividad se explican por cambio tecnológico, con fuertes diferencias regionales | E11: Utilizable | F11: El DOI proporcionado funciona correctamente y permite consultar el artículo completo. La lectura del documento confirma la relevancia atribuida por la IA. | G11: La referencia, el acceso al texto completo y la afirmación fueron confirmados directamente en el artículo.
A12: =Referencias!A12 -> R11 | B12: =IF(Referencias!D12="","",Referencias!D12) -> C | C12: =IF(Referencias!E12="","",Referencias!E12) -> Francisco Javier Maza Ávila, Juan Carlos Vergara Schmalbach y Raúl Román Romero. (2017).Eficiencia y productividad en la cobertura de las universidades públicas colombianas | D12: =IF(Referencias!G12="","",Referencias!G12) -> Evalúa la evolución de la productividad en la cobertura de 32 universidades públicas colombianas (2003-2012) mediante el índice de Malmquist, encontrando un crecimiento promedio anual del 9% en la productividad impulsado fundamentalmente por avances tecnológicos | E12: Utilizable | F12: Tanto la referencia como la URL funcionan correctamente y permiten visualizar el PDF completo. La lectura del documento confirma la afirmación atribuida por la IA. | G12: La referencia, el acceso al texto completo y la afirmación fueron confirmados directamente en el artículo.
A13: =Referencias!A13 -> R12 | B13: =IF(Referencias!D13="","",Referencias!D13) -> C | C13: =IF(Referencias!E13="","",Referencias!E13) -> Morales-Piñero, Niño-Muñoz, & Lesmes-Cardenas (2022).Gestión Pública o Privada de las Universidades: ¿Cuál es la Opción más Eficiente para una Política Pública en Educación Superior en Colombia? | D13: =IF(Referencias!G13="","",Referencias!G13) -> Emplea el índice Global Malmquist-Luenberger (GML) con metafronteras DEA para evaluar la productividad y la eficiencia de 122 universidades públicas y privadas colombianas considerando bad outputs como los egresados no vinculados al mercado laboral formal | E13: Utilizable | F13: Tanto la referencia como la URL funcionan correctamente y permiten visualizar el PDF completo. La lectura del documento confirma la afirmación atribuida por la IA. | G13: La referencia, el acceso al texto completo y la afirmación fueron confirmados directamente en el artículo.
... A46: =Referencias!A46 -> R45 | B46: =IF(Referencias!D46="","",Referencias!D46) -> C | C46: =IF(Referencias!E46="","",Referencias!E46) -> Visbal-Cadavid, D., Martínez-Gómez, M., & Guijarro, F. (2017). Assessing the Efficiency of Public Universities through DEA. A Case Study. Sustainability, 9(8), 1416. | D46: =IF(Referencias!G46="","",Referencias!G46) -> Evalúa 32 universidades públicas y consolida la metodología de medir la calidad de los egresados introduciendo en la frontera DEA el número ponderado de estudiantes en el quintil superior de Saber Pro. | E46: Utilizable | F46: La referencia y la URL funcionan correctamente. La URL dirige a una fuente que permite descargar el PDF completo y la lectura del artículo confirma la afirmación atribuida. | G46: La referencia, el acceso al texto completo y la afirmación fueron confirmados directamente en el artículo.
A47: =Referencias!A47 -> R46 | B47: =IF(Referencias!D47="","",Referencias!D47) | C47: =IF(Referencias!E47="","",Referencias!E47) | D47: =IF(Referencias!G47="","",Referencias!G47)
A48: =Referencias!A48 -> R47 | B48: =IF(Referencias!D48="","",Referencias!D48) | C48: =IF(Referencias!E48="","",Referencias!E48) | D48: =IF(Referencias!G48="","",Referencias!G48)
A49: =Referencias!A49 -> R48 | B49: =IF(Referencias!D49="","",Referencias!D49) | C49: =IF(Referencias!E49="","",Referencias!E49) | D49: =IF(Referencias!G49="","",Referencias!G49)
A50: =Referencias!A50 -> R49 | B50: =IF(Referencias!D50="","",Referencias!D50) | C50: =IF(Referencias!E50="","",Referencias!E50) | D50: =IF(Referencias!G50="","",Referencias!G50)
A51: =Referencias!A51 -> R50 | B51: =IF(Referencias!D51="","",Referencias!D51) | C51: =IF(Referencias!E51="","",Referencias!E51) | D51: =IF(Referencias!G51="","",Referencias!G51)
A52: =Referencias!A52 -> R51 | B52: =IF(Referencias!D52="","",Referencias!D52) | C52: =IF(Referencias!E52="","",Referencias!E52) | D52: =IF(Referencias!G52="","",Referencias!G52)
A53: =Referencias!A53 -> R52 | B53: =IF(Referencias!D53="","",Referencias!D53) | C53: =IF(Referencias!E53="","",Referencias!E53) | D53: =IF(Referencias!G53="","",Referencias!G53)
A54: =Referencias!A54 -> R53 | B54: =IF(Referencias!D54="","",Referencias!D54) | C54: =IF(Referencias!E54="","",Referencias!E54) | D54: =IF(Referencias!G54="","",Referencias!G54)
A55: =Referencias!A55 -> R54 | B55: =IF(Referencias!D55="","",Referencias!D55) | C55: =IF(Referencias!E55="","",Referencias!E55) | D55: =IF(Referencias!G55="","",Referencias!G55)
A56: =Referencias!A56 -> R55 | B56: =IF(Referencias!D56="","",Referencias!D56) | C56: =IF(Referencias!E56="","",Referencias!E56) | D56: =IF(Referencias!G56="","",Referencias!G56)
A57: =Referencias!A57 -> R56 | B57: =IF(Referencias!D57="","",Referencias!D57) | C57: =IF(Referencias!E57="","",Referencias!E57) | D57: =IF(Referencias!G57="","",Referencias!G57)
A58: =Referencias!A58 -> R57 | B58: =IF(Referencias!D58="","",Referencias!D58) | C58: =IF(Referencias!E58="","",Referencias!E58) | D58: =IF(Referencias!G58="","",Referencias!G58)
... A73: =Referencias!A73 -> R72 | B73: =IF(Referencias!D73="","",Referencias!D73) | C73: =IF(Referencias!E73="","",Referencias!E73) | D73: =IF(Referencias!G73="","",Referencias!G73)

Sheet Clasif_Anderson
A1: ID | B1: Tratamiento | C1: Referencia | D1: Afirmación atribuida | E1: Clasificación | F1: Cómo la verifiqué (DOI/URL encontrado o búsqueda hecha) | G1: Nota (metadatos erróneos, solo resumen, etc.)
A2: =Referencias!A2 -> R01 | B2: =IF(Referencias!D2="","",Referencias!D2) -> A | C2: =IF(Referencias!E2="","",Referencias!E2) -> Worthington, A. C., & Lee, B. L. (2008). Efficiency, technology and productivity change in Australian universities, 1998–2003. | D2: =IF(Referencias!G2="","",Referencias!G2) -> Worthington y Lee (2008) aplican el índice de Malmquist a 35 universidades australianas durante el periodo 1998-2003 para medir el crecimiento de la productividad y descomponerlo en cambios de eficiencia técnica y progreso tecnológico. El estudio encuentra un crecimiento promedio anual de la productividad del 3,3%, atribuido principalmente al progreso tecnológico. | E2: Utilizable | F2: Búsqueda manual por título en bases de datos. El enlace de la IA está roto. El DOI verdadero es: 10.1016/j.econedurev.2006.09.012 | G2: DOI incorrecto: El artículo y la cifra son reales, pero la IA se inventó el DOI (puso 10.006 al final en lugar de 09.012).
